the run number is: 8424
/project/lgrandi/anaconda3/lib/python3.5/importlib/_bootstrap.py:222: RuntimeWarning: numpy.dtype size changed, may indicate binary incompatibility. Expected 96, got 88
  return f(*args, **kwds)
/home/mlotfi/xom/xom/backend/src/get_dataframes.py:45: UserWarning: THIS NEEDS TO BE LOOKED AT ONCE XENONnT STARTS TAKING DATA
  warnings.warn("THIS NEEDS TO BE LOOKED AT ONCE XENONnT STARTS TAKING DATA")
Straxen is not loaded
the error No module named 'straxen'
The procesManager has the following parameters:
run_id: 8424
run_name:170403_1418
source:kr
datatype=calibration
output folder:/scratch/midway2/mlotfi/v1.0/8424
plugins:  event_info, corrected_areas type: <class 'str'>
these are the plugins you are going to use:  ('event_info', 'corrected_areas')
 the errro name 'straxen' is not defined
Traceback (most recent call last):
  File "./processManager", line 152, in <module>
    main()
  File "./processManager", line 117, in main
    df = dataFrame.get_data()
  File "/home/mlotfi/xom/xom/backend/src/get_dataframes.py", line 64, in get_data
    return df
UnboundLocalError: local variable 'df' referenced before assignment
sending incremental file list
rsync: link_stat "/scratch/midway2/mlotfi/v1.0" failed: No such file or directory (2)

sent 12 bytes  received 12 bytes  6.86 bytes/sec
total size is 0  speedup is 0.00
rsync error: some files/attrs were not transferred (see previous errors) (code 23) at main.c(1052) [sender=3.0.9]
There is problem syncing the run 8424
the run number is: 8424
/project/lgrandi/anaconda3/lib/python3.5/importlib/_bootstrap.py:222: RuntimeWarning: numpy.dtype size changed, may indicate binary incompatibility. Expected 96, got 88
  return f(*args, **kwds)
/home/mlotfi/xom/xom/backend/src/get_dataframes.py:45: UserWarning: THIS NEEDS TO BE LOOKED AT ONCE XENONnT STARTS TAKING DATA
  warnings.warn("THIS NEEDS TO BE LOOKED AT ONCE XENONnT STARTS TAKING DATA")
Straxen is not loaded
the error No module named 'straxen'
The procesManager has the following parameters:
run_id: 8424
run_name:170403_1418
source:kr
datatype=calibration
output folder:/scratch/midway2/mlotfi/v2.0/8424
plugins:  event_info, corrected_areas type: <class 'str'>
these are the plugins you are going to use:  ('event_info', 'corrected_areas')
 the errro name 'straxen' is not defined
Traceback (most recent call last):
  File "./processManager", line 152, in <module>
    main()
  File "./processManager", line 117, in main
    df = dataFrame.get_data()
  File "/home/mlotfi/xom/xom/backend/src/get_dataframes.py", line 64, in get_data
    return df
UnboundLocalError: local variable 'df' referenced before assignment
sending incremental file list
rsync: link_stat "/scratch/midway2/mlotfi/v2.0" failed: No such file or directory (2)

sent 12 bytes  received 12 bytes  6.86 bytes/sec
total size is 0  speedup is 0.00
rsync error: some files/attrs were not transferred (see previous errors) (code 23) at main.c(1052) [sender=3.0.9]
There is problem syncing the run 8424
the run number is: 9200
/project/lgrandi/anaconda3/lib/python3.5/importlib/_bootstrap.py:222: RuntimeWarning: numpy.dtype size changed, may indicate binary incompatibility. Expected 96, got 88
  return f(*args, **kwds)
/home/mlotfi/xom/xom/backend/src/get_dataframes.py:45: UserWarning: THIS NEEDS TO BE LOOKED AT ONCE XENONnT STARTS TAKING DATA
  warnings.warn("THIS NEEDS TO BE LOOKED AT ONCE XENONnT STARTS TAKING DATA")
Straxen is not loaded
the error No module named 'straxen'
The procesManager has the following parameters:
run_id: 9200
run_name:170501_2030
source:kr
datatype=calibration
output folder:/scratch/midway2/mlotfi/v1.0/9200
plugins:  event_info, corrected_areas type: <class 'str'>
these are the plugins you are going to use:  ('event_info', 'corrected_areas')
 the errro name 'straxen' is not defined
Traceback (most recent call last):
  File "./processManager", line 152, in <module>
    main()
  File "./processManager", line 117, in main
    df = dataFrame.get_data()
  File "/home/mlotfi/xom/xom/backend/src/get_dataframes.py", line 64, in get_data
    return df
UnboundLocalError: local variable 'df' referenced before assignment
sending incremental file list
rsync: link_stat "/scratch/midway2/mlotfi/v1.0" failed: No such file or directory (2)

sent 12 bytes  received 12 bytes  6.86 bytes/sec
total size is 0  speedup is 0.00
rsync error: some files/attrs were not transferred (see previous errors) (code 23) at main.c(1052) [sender=3.0.9]
There is problem syncing the run 9200
the run number is: 9200
/project/lgrandi/anaconda3/lib/python3.5/importlib/_bootstrap.py:222: RuntimeWarning: numpy.dtype size changed, may indicate binary incompatibility. Expected 96, got 88
  return f(*args, **kwds)
/home/mlotfi/xom/xom/backend/src/get_dataframes.py:45: UserWarning: THIS NEEDS TO BE LOOKED AT ONCE XENONnT STARTS TAKING DATA
  warnings.warn("THIS NEEDS TO BE LOOKED AT ONCE XENONnT STARTS TAKING DATA")
Straxen is not loaded
the error No module named 'straxen'
The procesManager has the following parameters:
run_id: 9200
run_name:170501_2030
source:kr
datatype=calibration
output folder:/scratch/midway2/mlotfi/v2.0/9200
plugins:  event_info, corrected_areas type: <class 'str'>
these are the plugins you are going to use:  ('event_info', 'corrected_areas')
 the errro name 'straxen' is not defined
Traceback (most recent call last):
  File "./processManager", line 152, in <module>
    main()
  File "./processManager", line 117, in main
    df = dataFrame.get_data()
  File "/home/mlotfi/xom/xom/backend/src/get_dataframes.py", line 64, in get_data
    return df
UnboundLocalError: local variable 'df' referenced before assignment
sending incremental file list
rsync: link_stat "/scratch/midway2/mlotfi/v2.0" failed: No such file or directory (2)

sent 12 bytes  received 12 bytes  6.86 bytes/sec
total size is 0  speedup is 0.00
rsync error: some files/attrs were not transferred (see previous errors) (code 23) at main.c(1052) [sender=3.0.9]
There is problem syncing the run 9200
the run number is: 16290
/project/lgrandi/anaconda3/lib/python3.5/importlib/_bootstrap.py:222: RuntimeWarning: numpy.dtype size changed, may indicate binary incompatibility. Expected 96, got 88
  return f(*args, **kwds)
/home/mlotfi/xom/xom/backend/src/get_dataframes.py:45: UserWarning: THIS NEEDS TO BE LOOKED AT ONCE XENONnT STARTS TAKING DATA
  warnings.warn("THIS NEEDS TO BE LOOKED AT ONCE XENONnT STARTS TAKING DATA")
Straxen is not loaded
the error No module named 'straxen'
The procesManager has the following parameters:
run_id: 16290
run_name:180124_1110
source:kr
datatype=calibration
output folder:/scratch/midway2/mlotfi/v1.0/16290
plugins:  event_info, corrected_areas type: <class 'str'>
these are the plugins you are going to use:  ('event_info', 'corrected_areas')
 the errro name 'straxen' is not defined
Traceback (most recent call last):
  File "./processManager", line 152, in <module>
    main()
  File "./processManager", line 117, in main
    df = dataFrame.get_data()
  File "/home/mlotfi/xom/xom/backend/src/get_dataframes.py", line 64, in get_data
    return df
UnboundLocalError: local variable 'df' referenced before assignment
sending incremental file list
rsync: link_stat "/scratch/midway2/mlotfi/v1.0" failed: No such file or directory (2)

sent 12 bytes  received 12 bytes  6.86 bytes/sec
total size is 0  speedup is 0.00
rsync error: some files/attrs were not transferred (see previous errors) (code 23) at main.c(1052) [sender=3.0.9]
There is problem syncing the run 16290
the run number is: 16290
/project/lgrandi/anaconda3/lib/python3.5/importlib/_bootstrap.py:222: RuntimeWarning: numpy.dtype size changed, may indicate binary incompatibility. Expected 96, got 88
  return f(*args, **kwds)
/home/mlotfi/xom/xom/backend/src/get_dataframes.py:45: UserWarning: THIS NEEDS TO BE LOOKED AT ONCE XENONnT STARTS TAKING DATA
  warnings.warn("THIS NEEDS TO BE LOOKED AT ONCE XENONnT STARTS TAKING DATA")
Straxen is not loaded
the error No module named 'straxen'
The procesManager has the following parameters:
run_id: 16290
run_name:180124_1110
source:kr
datatype=calibration
output folder:/scratch/midway2/mlotfi/v2.0/16290
plugins:  event_info, corrected_areas type: <class 'str'>
these are the plugins you are going to use:  ('event_info', 'corrected_areas')
 the errro name 'straxen' is not defined
Traceback (most recent call last):
  File "./processManager", line 152, in <module>
    main()
  File "./processManager", line 117, in main
    df = dataFrame.get_data()
  File "/home/mlotfi/xom/xom/backend/src/get_dataframes.py", line 64, in get_data
    return df
UnboundLocalError: local variable 'df' referenced before assignment
sending incremental file list
rsync: link_stat "/scratch/midway2/mlotfi/v2.0" failed: No such file or directory (2)

sent 12 bytes  received 12 bytes  6.86 bytes/sec
total size is 0  speedup is 0.00
rsync error: some files/attrs were not transferred (see previous errors) (code 23) at main.c(1052) [sender=3.0.9]
There is problem syncing the run 16290
the run number is: 14639
/project/lgrandi/anaconda3/lib/python3.5/importlib/_bootstrap.py:222: RuntimeWarning: numpy.dtype size changed, may indicate binary incompatibility. Expected 96, got 88
  return f(*args, **kwds)
/home/mlotfi/xom/xom/backend/src/get_dataframes.py:45: UserWarning: THIS NEEDS TO BE LOOKED AT ONCE XENONnT STARTS TAKING DATA
  warnings.warn("THIS NEEDS TO BE LOOKED AT ONCE XENONnT STARTS TAKING DATA")
Straxen is not loaded
the error No module named 'straxen'
The procesManager has the following parameters:
run_id: 14639
run_name:171120_2120
source:kr
datatype=calibration
output folder:/scratch/midway2/mlotfi/v1.0/14639
plugins:  event_info, corrected_areas type: <class 'str'>
these are the plugins you are going to use:  ('event_info', 'corrected_areas')
 the errro name 'straxen' is not defined
Traceback (most recent call last):
  File "./processManager", line 152, in <module>
    main()
  File "./processManager", line 117, in main
    df = dataFrame.get_data()
  File "/home/mlotfi/xom/xom/backend/src/get_dataframes.py", line 64, in get_data
    return df
UnboundLocalError: local variable 'df' referenced before assignment
sending incremental file list
rsync: link_stat "/scratch/midway2/mlotfi/v1.0" failed: No such file or directory (2)

sent 12 bytes  received 12 bytes  6.86 bytes/sec
total size is 0  speedup is 0.00
rsync error: some files/attrs were not transferred (see previous errors) (code 23) at main.c(1052) [sender=3.0.9]
There is problem syncing the run 14639
the run number is: 14639
/project/lgrandi/anaconda3/lib/python3.5/importlib/_bootstrap.py:222: RuntimeWarning: numpy.dtype size changed, may indicate binary incompatibility. Expected 96, got 88
  return f(*args, **kwds)
/home/mlotfi/xom/xom/backend/src/get_dataframes.py:45: UserWarning: THIS NEEDS TO BE LOOKED AT ONCE XENONnT STARTS TAKING DATA
  warnings.warn("THIS NEEDS TO BE LOOKED AT ONCE XENONnT STARTS TAKING DATA")
Straxen is not loaded
the error No module named 'straxen'
The procesManager has the following parameters:
run_id: 14639
run_name:171120_2120
source:kr
datatype=calibration
output folder:/scratch/midway2/mlotfi/v2.0/14639
plugins:  event_info, corrected_areas type: <class 'str'>
these are the plugins you are going to use:  ('event_info', 'corrected_areas')
 the errro name 'straxen' is not defined
Traceback (most recent call last):
  File "./processManager", line 152, in <module>
    main()
  File "./processManager", line 117, in main
    df = dataFrame.get_data()
  File "/home/mlotfi/xom/xom/backend/src/get_dataframes.py", line 64, in get_data
    return df
UnboundLocalError: local variable 'df' referenced before assignment
sending incremental file list
rsync: link_stat "/scratch/midway2/mlotfi/v2.0" failed: No such file or directory (2)

sent 12 bytes  received 12 bytes  6.86 bytes/sec
total size is 0  speedup is 0.00
rsync error: some files/attrs were not transferred (see previous errors) (code 23) at main.c(1052) [sender=3.0.9]
There is problem syncing the run 14639
the run number is: 13556
/project/lgrandi/anaconda3/lib/python3.5/importlib/_bootstrap.py:222: RuntimeWarning: numpy.dtype size changed, may indicate binary incompatibility. Expected 96, got 88
  return f(*args, **kwds)
/home/mlotfi/xom/xom/backend/src/get_dataframes.py:45: UserWarning: THIS NEEDS TO BE LOOKED AT ONCE XENONnT STARTS TAKING DATA
  warnings.warn("THIS NEEDS TO BE LOOKED AT ONCE XENONnT STARTS TAKING DATA")
Straxen is not loaded
the error No module named 'straxen'
The procesManager has the following parameters:
run_id: 13556
run_name:171009_0851
source:kr
datatype=calibration
output folder:/scratch/midway2/mlotfi/v1.0/13556
plugins:  event_info, corrected_areas type: <class 'str'>
these are the plugins you are going to use:  ('event_info', 'corrected_areas')
 the errro name 'straxen' is not defined
Traceback (most recent call last):
  File "./processManager", line 152, in <module>
    main()
  File "./processManager", line 117, in main
    df = dataFrame.get_data()
  File "/home/mlotfi/xom/xom/backend/src/get_dataframes.py", line 64, in get_data
    return df
UnboundLocalError: local variable 'df' referenced before assignment
sending incremental file list
rsync: link_stat "/scratch/midway2/mlotfi/v1.0" failed: No such file or directory (2)

sent 12 bytes  received 12 bytes  6.86 bytes/sec
total size is 0  speedup is 0.00
rsync error: some files/attrs were not transferred (see previous errors) (code 23) at main.c(1052) [sender=3.0.9]
There is problem syncing the run 13556
the run number is: 13556
/project/lgrandi/anaconda3/lib/python3.5/importlib/_bootstrap.py:222: RuntimeWarning: numpy.dtype size changed, may indicate binary incompatibility. Expected 96, got 88
  return f(*args, **kwds)
/home/mlotfi/xom/xom/backend/src/get_dataframes.py:45: UserWarning: THIS NEEDS TO BE LOOKED AT ONCE XENONnT STARTS TAKING DATA
  warnings.warn("THIS NEEDS TO BE LOOKED AT ONCE XENONnT STARTS TAKING DATA")
Straxen is not loaded
the error No module named 'straxen'
The procesManager has the following parameters:
run_id: 13556
run_name:171009_0851
source:kr
datatype=calibration
output folder:/scratch/midway2/mlotfi/v2.0/13556
plugins:  event_info, corrected_areas type: <class 'str'>
these are the plugins you are going to use:  ('event_info', 'corrected_areas')
 the errro name 'straxen' is not defined
Traceback (most recent call last):
  File "./processManager", line 152, in <module>
    main()
  File "./processManager", line 117, in main
    df = dataFrame.get_data()
  File "/home/mlotfi/xom/xom/backend/src/get_dataframes.py", line 64, in get_data
    return df
UnboundLocalError: local variable 'df' referenced before assignment
sending incremental file list
rsync: link_stat "/scratch/midway2/mlotfi/v2.0" failed: No such file or directory (2)

sent 12 bytes  received 12 bytes  6.86 bytes/sec
total size is 0  speedup is 0.00
rsync error: some files/attrs were not transferred (see previous errors) (code 23) at main.c(1052) [sender=3.0.9]
There is problem syncing the run 13556
the run number is: 12104
/project/lgrandi/anaconda3/lib/python3.5/importlib/_bootstrap.py:222: RuntimeWarning: numpy.dtype size changed, may indicate binary incompatibility. Expected 96, got 88
  return f(*args, **kwds)
/home/mlotfi/xom/xom/backend/src/get_dataframes.py:45: UserWarning: THIS NEEDS TO BE LOOKED AT ONCE XENONnT STARTS TAKING DATA
  warnings.warn("THIS NEEDS TO BE LOOKED AT ONCE XENONnT STARTS TAKING DATA")
Straxen is not loaded
the error No module named 'straxen'
The procesManager has the following parameters:
run_id: 12104
run_name:170814_1340
source:kr
datatype=calibration
output folder:/scratch/midway2/mlotfi/v1.0/12104
plugins:  event_info, corrected_areas type: <class 'str'>
these are the plugins you are going to use:  ('event_info', 'corrected_areas')
 the errro name 'straxen' is not defined
Traceback (most recent call last):
  File "./processManager", line 152, in <module>
    main()
  File "./processManager", line 117, in main
    df = dataFrame.get_data()
  File "/home/mlotfi/xom/xom/backend/src/get_dataframes.py", line 64, in get_data
    return df
UnboundLocalError: local variable 'df' referenced before assignment
sending incremental file list
rsync: link_stat "/scratch/midway2/mlotfi/v1.0" failed: No such file or directory (2)

sent 12 bytes  received 12 bytes  6.86 bytes/sec
total size is 0  speedup is 0.00
rsync error: some files/attrs were not transferred (see previous errors) (code 23) at main.c(1052) [sender=3.0.9]
There is problem syncing the run 12104
the run number is: 12104
/project/lgrandi/anaconda3/lib/python3.5/importlib/_bootstrap.py:222: RuntimeWarning: numpy.dtype size changed, may indicate binary incompatibility. Expected 96, got 88
  return f(*args, **kwds)
/home/mlotfi/xom/xom/backend/src/get_dataframes.py:45: UserWarning: THIS NEEDS TO BE LOOKED AT ONCE XENONnT STARTS TAKING DATA
  warnings.warn("THIS NEEDS TO BE LOOKED AT ONCE XENONnT STARTS TAKING DATA")
Straxen is not loaded
the error No module named 'straxen'
The procesManager has the following parameters:
run_id: 12104
run_name:170814_1340
source:kr
datatype=calibration
output folder:/scratch/midway2/mlotfi/v2.0/12104
plugins:  event_info, corrected_areas type: <class 'str'>
these are the plugins you are going to use:  ('event_info', 'corrected_areas')
 the errro name 'straxen' is not defined
Traceback (most recent call last):
  File "./processManager", line 152, in <module>
    main()
  File "./processManager", line 117, in main
    df = dataFrame.get_data()
  File "/home/mlotfi/xom/xom/backend/src/get_dataframes.py", line 64, in get_data
    return df
UnboundLocalError: local variable 'df' referenced before assignment
sending incremental file list
rsync: link_stat "/scratch/midway2/mlotfi/v2.0" failed: No such file or directory (2)

sent 12 bytes  received 12 bytes  6.86 bytes/sec
total size is 0  speedup is 0.00
rsync error: some files/attrs were not transferred (see previous errors) (code 23) at main.c(1052) [sender=3.0.9]
There is problem syncing the run 12104
the run number is: 10959
/project/lgrandi/anaconda3/lib/python3.5/importlib/_bootstrap.py:222: RuntimeWarning: numpy.dtype size changed, may indicate binary incompatibility. Expected 96, got 88
  return f(*args, **kwds)
/home/mlotfi/xom/xom/backend/src/get_dataframes.py:45: UserWarning: THIS NEEDS TO BE LOOKED AT ONCE XENONnT STARTS TAKING DATA
  warnings.warn("THIS NEEDS TO BE LOOKED AT ONCE XENONnT STARTS TAKING DATA")
Straxen is not loaded
the error No module named 'straxen'
The procesManager has the following parameters:
run_id: 10959
run_name:170703_1153
source:kr
datatype=calibration
output folder:/scratch/midway2/mlotfi/v1.0/10959
plugins:  event_info, corrected_areas type: <class 'str'>
these are the plugins you are going to use:  ('event_info', 'corrected_areas')
 the errro name 'straxen' is not defined
Traceback (most recent call last):
  File "./processManager", line 152, in <module>
    main()
  File "./processManager", line 117, in main
    df = dataFrame.get_data()
  File "/home/mlotfi/xom/xom/backend/src/get_dataframes.py", line 64, in get_data
    return df
UnboundLocalError: local variable 'df' referenced before assignment
sending incremental file list
rsync: link_stat "/scratch/midway2/mlotfi/v1.0" failed: No such file or directory (2)

sent 12 bytes  received 12 bytes  9.60 bytes/sec
total size is 0  speedup is 0.00
rsync error: some files/attrs were not transferred (see previous errors) (code 23) at main.c(1052) [sender=3.0.9]
There is problem syncing the run 10959
the run number is: 10959
/project/lgrandi/anaconda3/lib/python3.5/importlib/_bootstrap.py:222: RuntimeWarning: numpy.dtype size changed, may indicate binary incompatibility. Expected 96, got 88
  return f(*args, **kwds)
/home/mlotfi/xom/xom/backend/src/get_dataframes.py:45: UserWarning: THIS NEEDS TO BE LOOKED AT ONCE XENONnT STARTS TAKING DATA
  warnings.warn("THIS NEEDS TO BE LOOKED AT ONCE XENONnT STARTS TAKING DATA")
Straxen is not loaded
the error No module named 'straxen'
The procesManager has the following parameters:
run_id: 10959
run_name:170703_1153
source:kr
datatype=calibration
output folder:/scratch/midway2/mlotfi/v2.0/10959
plugins:  event_info, corrected_areas type: <class 'str'>
these are the plugins you are going to use:  ('event_info', 'corrected_areas')
 the errro name 'straxen' is not defined
Traceback (most recent call last):
  File "./processManager", line 152, in <module>
    main()
  File "./processManager", line 117, in main
    df = dataFrame.get_data()
  File "/home/mlotfi/xom/xom/backend/src/get_dataframes.py", line 64, in get_data
    return df
UnboundLocalError: local variable 'df' referenced before assignment
sending incremental file list
rsync: link_stat "/scratch/midway2/mlotfi/v2.0" failed: No such file or directory (2)

sent 12 bytes  received 12 bytes  9.60 bytes/sec
total size is 0  speedup is 0.00
rsync error: some files/attrs were not transferred (see previous errors) (code 23) at main.c(1052) [sender=3.0.9]
There is problem syncing the run 10959
the run number is: 10265
/project/lgrandi/anaconda3/lib/python3.5/importlib/_bootstrap.py:222: RuntimeWarning: numpy.dtype size changed, may indicate binary incompatibility. Expected 96, got 88
  return f(*args, **kwds)
/home/mlotfi/xom/xom/backend/src/get_dataframes.py:45: UserWarning: THIS NEEDS TO BE LOOKED AT ONCE XENONnT STARTS TAKING DATA
  warnings.warn("THIS NEEDS TO BE LOOKED AT ONCE XENONnT STARTS TAKING DATA")
Straxen is not loaded
the error No module named 'straxen'
The procesManager has the following parameters:
run_id: 10265
run_name:170607_0919
source:kr
datatype=calibration
output folder:/scratch/midway2/mlotfi/v1.0/10265
plugins:  event_info, corrected_areas type: <class 'str'>
these are the plugins you are going to use:  ('event_info', 'corrected_areas')
 the errro name 'straxen' is not defined
Traceback (most recent call last):
  File "./processManager", line 152, in <module>
    main()
  File "./processManager", line 117, in main
    df = dataFrame.get_data()
  File "/home/mlotfi/xom/xom/backend/src/get_dataframes.py", line 64, in get_data
    return df
UnboundLocalError: local variable 'df' referenced before assignment
sending incremental file list
rsync: link_stat "/scratch/midway2/mlotfi/v1.0" failed: No such file or directory (2)

sent 12 bytes  received 12 bytes  9.60 bytes/sec
total size is 0  speedup is 0.00
rsync error: some files/attrs were not transferred (see previous errors) (code 23) at main.c(1052) [sender=3.0.9]
There is problem syncing the run 10265
the run number is: 10265
/project/lgrandi/anaconda3/lib/python3.5/importlib/_bootstrap.py:222: RuntimeWarning: numpy.dtype size changed, may indicate binary incompatibility. Expected 96, got 88
  return f(*args, **kwds)
/home/mlotfi/xom/xom/backend/src/get_dataframes.py:45: UserWarning: THIS NEEDS TO BE LOOKED AT ONCE XENONnT STARTS TAKING DATA
  warnings.warn("THIS NEEDS TO BE LOOKED AT ONCE XENONnT STARTS TAKING DATA")
Straxen is not loaded
the error No module named 'straxen'
The procesManager has the following parameters:
run_id: 10265
run_name:170607_0919
source:kr
datatype=calibration
output folder:/scratch/midway2/mlotfi/v2.0/10265
plugins:  event_info, corrected_areas type: <class 'str'>
these are the plugins you are going to use:  ('event_info', 'corrected_areas')
 the errro name 'straxen' is not defined
Traceback (most recent call last):
  File "./processManager", line 152, in <module>
    main()
  File "./processManager", line 117, in main
    df = dataFrame.get_data()
  File "/home/mlotfi/xom/xom/backend/src/get_dataframes.py", line 64, in get_data
    return df
UnboundLocalError: local variable 'df' referenced before assignment
sending incremental file list
rsync: link_stat "/scratch/midway2/mlotfi/v2.0" failed: No such file or directory (2)

sent 12 bytes  received 12 bytes  9.60 bytes/sec
total size is 0  speedup is 0.00
rsync error: some files/attrs were not transferred (see previous errors) (code 23) at main.c(1052) [sender=3.0.9]
There is problem syncing the run 10265
